Workbook
Name _1Excel_BuiltIn__FilterDatabase_12_1: Real_2007!$A$1:$F$4604
Name dois: IF(#REF!="X",0,#REF!)
Name Excel_BuiltIn__FilterDatabase_10_1: ItaU!$A$1:$E$1390
Name Excel_BuiltIn__FilterDatabase_12_1: ItauVisa!$A$1:$F$21
Name Excel_BuiltIn__FilterDatabase_13: ItauMasterCard!$A$1:$F$471
Name Excel_BuiltIn__FilterDatabase_16: RealVisa_2007!$A$1:$F$621
Name Excel_BuiltIn__FilterDatabase_16_1: Parcelamentos!$A$1:$G$662
Name Excel_BuiltIn__FilterDatabase_18: ItauVisa!$A$1:$F$1421
Name Excel_BuiltIn__FilterDatabase_19: ItauMasterCard!$A$1:$F$477
Name Excel_BuiltIn__FilterDatabase_25_1: PoupanCaItau!$A$1:$E$1
Name Excel_BuiltIn__FilterDatabase_44: Banespa!$A$1:$F$78
Name Excel_BuiltIn__FilterDatabase_45: HSBC!$A$1:$E$943
Name Excel_BuiltIn__FilterDatabase_47: HSBCVisa!$A$1:$F$94
Name Excel_BuiltIn__FilterDatabase_49: Banco1MasterCard!$A$1:$F$160
Name Excel_BuiltIn__FilterDatabase_5: CARTOES!$A$1:$K$25
Name Excel_BuiltIn__FilterDatabase_50: Banco1!$A$1:$E$795
Name Excel_BuiltIn__FilterDatabase_52: Banco1MasterCard!$A$1:$F$160
Name Excel_BuiltIn__FilterDatabase_53: UnibancoVisa!$A$1:$F$62
Name Excel_BuiltIn__FilterDatabase_56: Amex!$A$1:$F$1
Name Excel_BuiltIn__FilterDatabase_57: CitiBank!$A$1:$E$475
Name Excel_BuiltIn__FilterDatabase_60: CitibankVisa!$A$1:$F$209
Name Excel_BuiltIn__FilterDatabase_61: CitiBankMastercard!$A$1:$F$180
Name Excel_BuiltIn__FilterDatabase_62: Real!$A$1:$E$581
Name Excel_BuiltIn__FilterDatabase_63: RealVisa!$A$1:$F$277
Name Excel_BuiltIn__FilterDatabase_7: TiposLancamentos!$A$1:$B$105
Name Excel_BuiltIn__FilterDatabase_8: Despesas!$A$1:$E$4128
Name SHARED_FORMULA_0: IF(#REF!="X",0,#REF!)
Name SHARED_FORMULA_0: IF(#REF!="X",0,#REF!)
Name SHARED_FORMULA_0: IF(#REF!="X",0,#REF!)
Name SHARED_FORMULA_0: IF(#REF!="X",0,#REF!)
Name SHARED_FORMULA_0: IF(#REF!="X",0,#REF!)
Name SHARED_FORMULA_0: IF(#REF!="X",0,#REF!)
Name SHARED_FORMULA_1: IF(#REF!="X",0,#REF!)
Name SHARED_FORMULA_1: IF(#REF!="X",0,#REF!)
Name SHARED_FORMULA_1: IF(#REF!="X",0,#REF!)
Name SHARED_FORMULA_1: IF(#REF!="X",0,#REF!)
Name SHARED_FORMULA_1: IF(#REF!="X",0,#REF!)
Name SHARED_FORMULA_1: IF(#REF!="X",0,#REF!)
Name SHARED_FORMULA_2: IF(#REF!="X",0,#REF!)
Name SHARED_FORMULA_2: IF(#REF!="X",0,#REF!)
Name SHARED_FORMULA_2: IF(#REF!="X",0,#REF!)
Name SHARED_FORMULA_2: IF(#REF!="X",0,#REF!)
Name SHARED_FORMULA_2: IF(#REF!="X",0,#REF!)
Name SHARED_FORMULA_2: IF(#REF!="X",0,#REF!)
Name SHARED_FORMULA_3: #REF!+1
Name SHARED_FORMULA_3: #REF!+1
Name SHARED_FORMULA_3: #REF!+1
Name SHARED_FORMULA_3: #REF!+1
Name SHARED_FORMULA_3: #REF!+1
Name SHARED_FORMULA_3: #REF!+1
Name SHARED_FORMULA_4: #REF!+1
Name SHARED_FORMULA_4: #REF!+1
Name SHARED_FORMULA_4: #REF!+1
Name SHARED_FORMULA_4: #REF!+1
Name SHARED_FORMULA_4: #REF!+1
Name SHARED_FORMULA_4: #REF!+1
Name SHARED_FORMULA_5: #REF!+1
Name SHARED_FORMULA_5: #REF!+1
Name SHARED_FORMULA_5: #REF!+1
Name SHARED_FORMULA_5: #REF!+1

Sheet TEMPLATE_empty
A1: Data | B1: TIPO | C1: DESCRICAO | D1: Credito | E1: Debito | F1: Subtotais | G1: Check
C2: Dezembro/2019
A3: 43800 | B3: =TiposLancamentos!B77 -> Esporádico | C3: Teste | D3: 0.01 | G3: X
A4: 43800 | B4: =TiposLancamentos!B78 -> Diferenças | C4: Teste | E4: 0.01 | G4: X
C5: CORTE DE FATURAMENTO | G5: ???
G20: ???
C21: Totais: | D21: =SUM(D2:D20) -> 0.01 | E21: =SUM(E2:E20) -> 0.01
C22: Saldo Presumido | E22: =D21-E21 -> 0
D24: Limite | E24: Posição | F24: Disponivel
B25: Valor Parcial da Fatura | E25: =E22 -> 0 | F25: =D25+E25 -> 0

Sheet GUIDING
A1: TABLE_NAME | B1: LOADABLE | C1: ACCOUNTING | D1: CLEANABLE
A2: GUIDING | B2: X
A3: GamesWishList | B3: X
A4: TiposLancamentos | B4: X
A5: Despesas | B5: X | C5: X | D5: X
A6: Banco1MasterCard | B6: X | C6: X | D6: X
A7: Banespa | B7: X | C7: X | D7: X
A8: ItauUniclassVisa | B8: X | C8: X | D8: X
A9: ItaU | B9: X | C9: X | D9: X
A10: Amazon_Master | B10: X | C10: X | D10: X
A11: BTG_Pactual | B11: X | C11: X | D11: X
A12: Santander | B12: X | C12: X | D12: X
A13: CrediCard_Master | B13: X | C13: X | D13: X
A14: XP_Inv_ContaC | B14: X | C14: X | D14: X
A15: NUBank_Master | B15: X | C15: X | D15: X
A16: XP_Inv_Visa | B16: X | C16: X | D16: X
... A20: RealVisa | B20: X | C20: X | D20: X
A21: Faturas de Cartão | B21: X
A22: PortoSeguro_Master | B22: X | C22: X | D22: X
A23: MagaLu_Visa_Plat | B23: X | C23: X | D23: X
A24: Filmes | B24: X
A25: Livros | B25: X
A26: Games | B26: X
A27: Lista de CDs | B27: X
A28: Lista de DVDs | B28: X
A29: Amex | B29: X | C29: X | D29: X
A30: Amex_2010 | B30: X | C30: X | D30: X
A31: Banco1 | B31: X | C31: X | D31: X
A32: Carefour | B32: X | C32: X | D32: X
A33: CartaoSubMaRiNo | B33: X | C33: X | D33: X
A34: CEF | B34: X | C34: X | D34: X
A35: CitiBank | B35: X | C35: X | D35: X
A36: CitiBankMastercard | B36: X | C36: X | D36: X
A37: CitibankVisa | B37: X | C37: X | D37: X
A38: DigioVisa | B38: X | C38: X | D38: X
A39: HSBC | B39: X | C39: X | D39: X
A40: HSBCVisa | B40: X | C40: X | D40: X
... A44: Nubank_ContaC | B44: X | C44: X | D44: X
A45: Parcelamentos | B45: X
A46: PortoSeguroVisa | B46: X | C46: X | D46: X
...

Sheet General_din_reports
A1: DEST_TABLE | B1: SHEETY | C1: REPORT_NAME
A2: LIVING_COSTS | B2: DR_001 | C2: Custos Com Moradia
A3: FUNNY_COSTS | B3: DR_002 | C3: Entreterimento

Sheet DR_001
A1: COLUMN_NAME
A2: AnoMes
A3: =TiposLancamentos!B2 -> Telefonia
A4: =TiposLancamentos!B3 -> Internet
A5: =TiposLancamentos!B8 -> Aluguel
A6: =TiposLancamentos!B9 -> Condominio
A7: =TiposLancamentos!B12 -> IPTU
A8: =TiposLancamentos!B6 -> Energia Eletrica
A9: =TiposLancamentos!B11 -> Coleta Municipal Lixo
A10: =TiposLancamentos!B10 -> Distr. Água Municipal
A11: =TiposLancamentos!B35 -> Tv à Cabo
A12: =TiposLancamentos!B14 -> Gás de cozinha
A13: =TiposLancamentos!B13 -> Moradia

Sheet DR_002
A1: COLUMN_NAME
A2: AnoMes
A3: =TiposLancamentos!B25 -> CD_DVD_BD
A4: =TiposLancamentos!B26 -> LIVROS
A5: =TiposLancamentos!B27 -> Jornais e revistas
A6: =TiposLancamentos!B28 -> ComicBook
A7: =TiposLancamentos!B29 -> Mangá
A8: =TiposLancamentos!B30 -> Cinema
A9: =TiposLancamentos!B90 -> Locadora
A10: =TiposLancamentos!B45 -> Online Services
A11: =TiposLancamentos!B36 -> Playstation 2
A12: =TiposLancamentos!B37 -> Playstation 3
A13: =TiposLancamentos!B38 -> Playstation 4
A14: =TiposLancamentos!B39 -> Playstation 5
A15: =TiposLancamentos!B42 -> PSP FAT 1K
A16: =TiposLancamentos!B91 -> PSP Slim 2000
A17: =TiposLancamentos!B40 -> PS Vita Slim 2k
A18: =TiposLancamentos!B41 -> PSP Slim 3k

Sheet GamesWishList
A1: Title | B1: Platform | C1: comprado | D1: data | E1: onde
A2: Bayonetta 2 | B2: Nintendo Switch
A3: Bayonetta 3 | B3: Nintendo Switch
A4: Bloodrayne | B4: PS2 | C4: X | D4: 45563 | E4: eBay.com US&A
A5: Bloodrayne 2 | B5: PS2 | C5: X | D5: 45549 | E5: Game collection Show
A6: Castlevania: lament of Innocence | B6: PS2 | C6: X | D6: 45917 | E6: gvl Games - whatsApp
A7: Devil May Cry | B7: PS2 | C7: X | D7: 45549 | E7: Game collection Show
A8: Devil May Cry 2 JP | B8: PS2 | C8: X | D8: 45549 | E8: Game collection Show
A9: Devil May Cry 3 Dante´s Awakening | B9: PS2 | C9: X | D9: 45549 | E9: Game collection Show
A10: Final Fantasy X | B10: PS2 | C10: X | D10: 45780 | E10: Pororó Games no Yabacura
A11: Final Fantasy X-2 | B11: PS2 | C11: X | D11: 45780 | E11: Old Tete Sound no Yabacuara
A12: Final Fantasy XII | B12: PS2 | C12: X | D12: 45554 | E12: eBay.com US&A
A13: Final Fantasy XII -COM LATA E DVD EXTRA | B13: PS2 | C13: X | D13: 45598 | E13: Number 1 Games na ExpoCanal3
A14: God of War (2005) | B14: PS2 | C14: X | D14: 45061 | E14: eBay.com US&A
A15: God of War II (2007) | B15: PS2 | C15: X | D15: 45058 | E15: eBay.com US&A
... A32: Resident Evil 4 Greatest Hits | B32: PS2 | C32: X | D32: 45534 | E32: AdautoWorld Colecionaveis
A33: Spawn: Armageddon | B33: PS2
A34: Syphn filterDark Mirror | B34: PS2 | C34: X | D34: 45549 | E34: Game collection Show
A35: Tourist trophy | B35: PS2 | C35: X | D35: 46058 | E35: Direto do Nelson Loia JR
A36: Alice: Madness Returns | B36: PS3 | C36: X | D36: 45078 | E36: Gabriel FB Market
A37: Alone In The Dark Inferno | B37: PS3 | C37: X | D37: 45068 | E37: MeuGameUsado
A38: Anarchy Reigns | B38: PS3 | C38: X | D38: 46004 | E38: HouseOfGames Taubate : Yabacuara
A39: Assassin´s Creed´s II | B39: PS3 | C39: x | D39: 45137 | E39: RetroCon 2023
A40: Assassin´s Creed´s III | B40: PS3 | C40: X | D40: 45353 | E40: Grupo Facebook PS3
A41: Assassin´s Creed´s IV Black Flag | B41: PS3 | C41: X | D41: 45353 | E41: Grupo Facebook PS3
A42: Asura's Wrath | B42: PS3 | C42: X | D42: 45078 | E42: Mercadolibre
A43: Bayonetta | B43: PS3 | C43: X | D43: 45182 | E43: Mercadolibre
A44: Berserk and the band of the Hawk | B44: PS3
A45: Beyond: Two Souls | B45: PS3 | C45: X | D45: 45059 | E45: Dika Games
A46: Bioshock | B46: PS3 | C46: X | D46: 45111 | E46: Anderson Pinto
A47: Bioshock Infinite | B47: PS3 | C47: X | D47: 45059 | E47: Dika Games
A48: Blades of Time | B48: PS3 | C48: X | D48: 45068 | E48: MeuGameUsado
A49: Body Count | B49: PS3 | C49: X | D49: 45742 | E49: Pereira Retro Games
A50: Bound by Flame | B50: PS3 | C50: X | D50: 45203 | E50: Mercadolibre
A51: Brütal Legend | B51: PS3 | C51: X | D51: 45073 | E51: Dika Games
A52: Bullet Storm | B52: PS3 | C52: X | D52: 45682 | E52: Natan Games no Atrium
A53: BulletStorm (Alternative cover) | B53: PS3 | C53: X | D53: 45789 | E53: Glaukera Games
A54: Burnout Paradise | B54: PS3
A55: Castlevania Lord of The Shadows | B55: PS3 | C55: X | D55: 45549 | E55: Game collection Show
A56: Castlevania Lord of The Shadows 2 | B56: PS3 | C56: X | D56: 45549 | E56: Game collection Show
...

Sheet Tarot_Decks
A1: # | B1: Nome do Deck | C1: Editora | D1: Autor(es) | E1: Livreto | F1: Digital | G1: Data da Compra | H1: Valor | I1: Onde foi Adquirido | J1: Tipo | K1: Chave Primária
A2: 1 | B2: Marselha Generico | C2: Alfabeto | D2: Brigite Zuraá | E2: SIM | F2: SIM | G2: 41836 | H2: 44.9 | I2: Saraiva de SCS | J2: Full Tarot Deck | K2: =CONCATENATE(TEXT(A2,"0000"),(TEXT(G2,"aaaammdd"))) -> 000120140716
A3: 2 | B3: O Tarô Universal de Waite | C3: Isis Brasil | D3: Edith Waite | E3: SIM | F3: Não | G3: 41836 | H3: 44.9 | I3: Saraiva de SCS | J3: Full Tarot Deck | K3: =CONCATENATE(TEXT(A3,"0000"),(TEXT(G3,"aaaammdd"))) -> 000220140716
A4: 3 | B4: Crowley Thoth | C4: US Games Inc. | D4: Aleister Crowley / Frieda Harris | E4: SIM | F4: SIM | G4: 41878 | H4: 74 | I4: Simbólika | J4: Full Tarot Deck | K4: =CONCATENATE(TEXT(A4,"0000"),(TEXT(G4,"aaaammdd"))) -> 000320140827
A5: 4 | B5: Renaissance | C5: US Games Inc. | D5: Brian Willians | E5: SIM | F5: SIM | G5: 41878 | H5: 74 | I5: Simbólika | J5: Full Tarot Deck | K5: =CONCATENATE(TEXT(A5,"0000"),(TEXT(G5,"aaaammdd"))) -> 000420140827
A6: 5 | B6: Mitológico | C6: Madras Brasil | D6: Juliet Sharman-Burke, Liz Greene | E6: SIM | F6: Não | G6: 41880 | H6: 72.9 | I6: Madras da Bienal do Livro | J6: Full Tarot Deck | K6: =CONCATENATE(TEXT(A6,"0000"),(TEXT(G6,"aaaammdd"))) -> 000520140829
A7: 6 | B7: Nei Naiff | C7: Nova Era | D7: Thais Linhares / Nei Naiff | E7: SIM | F7: Não | G7: 41900 | H7: 69 | I7: Direto da Editora | J7: Full Tarot Deck | K7: =CONCATENATE(TEXT(A7,"0000"),(TEXT(G7,"aaaammdd"))) -> 000620140918
A8: 7 | B8: Tarô Intuitivo | C8: Isis Brasil | D8: DAVID MILES | E8: SIM | F8: Não | G8: 41974 | H8: 59.92 | I8: Simbólika | J8: Full Tarot Deck | K8: =CONCATENATE(TEXT(A8,"0000"),(TEXT(G8,"aaaammdd"))) -> 000720141201
A9: 8 | B9: Lo Scarabeo | C9: Lo Scarabeo | D9: Mark McElroy, Anna Lazzarini | E9: SIM | F9: SIM | G9: 41974 | H9: 71.25 | I9: Simbólika | J9: Full Tarot Deck | K9: =CONCATENATE(TEXT(A9,"0000"),(TEXT(G9,"aaaammdd"))) -> 000820141201
A10: 9 | B10: Rider Waite classical Original Tarot | C10: US Games Inc. | D10: A.E. Waite / P. C. Smith | E10: SIM | F10: SIM | G10: 41984 | H10: 72 | I10: US Games Brasil | J10: Full Tarot Deck | K10: =CONCATENATE(TEXT(A10,"0000"),(TEXT(G10,"aaaammdd"))) -> 000920141211
A11: 10 | B11: Hermetic Kaballah Tarot 2 | C11: Daemon Editora | D11: Marcelo Deldebbio / Rodrigo Grola | E11: Não | F11: Não | G11: 41996 | H11: 103.7 | I11: Daemon Editora | J11: Full Tarot Deck | K11: =CONCATENATE(TEXT(A11,"0000"),(TEXT(G11,"aaaammdd"))) -> 001020141223
A12: 11 | B12: Fenestra tarot | C12: US Games Inc. | D12: Chatriya | E12: SIM | F12: SIM | G12: 42020 | H12: 69 | I12: Simbólika | J12: Full Tarot Deck | K12: =CONCATENATE(TEXT(A12,"0000"),(TEXT(G12,"aaaammdd"))) -> 001120150116
A13: 12 | B13: Namur TaroT | C13: N/A | D13: Namur Gopalla / Martha Leyrós | E13: Não | F13: Não | G13: 42059 | H13: 100 | I13: Direto do Autor | J13: Full Tarot Deck | K13: =CONCATENATE(TEXT(A13,"0000"),(TEXT(G13,"aaaammdd"))) -> 001220150224
A14: 13 | B14: The B.O.T.A. Full Tarot Deck | C14: B.O.T.A. | E14: Não | F14: Não | G14: 42102 | H14: 69.93 | I14: Direto do Autor | J14: Full Tarot Deck | K14: =CONCATENATE(TEXT(A14,"0000"),(TEXT(G14,"aaaammdd"))) -> 001320150408
A15: 14 | B15: Visconti Sforza | C15: US Games Inc. | D15: Pierpont Morgan | E15: SIM | F15: SIM | G15: 42113 | H15: 200 | I15: O Argonauta - Feira Mistica Paulista | J15: Full Tarot Deck | K15: =CONCATENATE(TEXT(A15,"0000"),(TEXT(G15,"aaaammdd"))) -> 001420150419
A16: 15 | B16: Radiant Rider Waite (Lata) Cristaiane | C16: US Games Inc. | D16: A.E. Waite / P. C. Smith | E16: SIM | F16: SIM | G16: 42113 | H16: 80 | I16: O Argonauta - Feira Mistica Paulista | J16: Full Tarot Deck | K16: =CONCATENATE(TEXT(A16,"0000"),(TEXT(G16,"aaaammdd"))) -> 001520150419
A17: 16 | B17: BIG B.O.T.A. Major Arcanas | C17: B.O.T.A. | E17: Não | F17: Não | G17: 42119 | H17: 88.34 | I17: Direto do Autor | J17: Full Tarot Deck | K17: =CONCATENATE(TEXT(A17,"0000"),(TEXT(G17,"aaaammdd"))) -> 001620150425
A18: 17 | B18: Pirates Tarot | C18: Lo Scarabeo | D18: Bepi Vigna, Michele Benevento, | E18: SIM | F18: SIM | G18: 42122 | H18: 63.81 | I18: Editora Pressagio | J18: Full Tarot Deck | K18: =CONCATENATE(TEXT(A18,"0000"),(TEXT(G18,"aaaammdd"))) -> 001720150428
A19: 18 | B19: Dark Royo tarot | C19: Lo Scarabeo | D19: Luis Royo | E19: SIM | F19: SIM | G19: 42122 | H19: 63.81 | I19: Editora Pressagio | J19: Full Tarot Deck | K19: =CONCATENATE(TEXT(A19,"0000"),(TEXT(G19,"aaaammdd"))) -> 001820150428
A20: 19 | B20: The Secrets Tarot | C20: Lo Scarabeo | D20: Marco Nizzoli | E20: SIM | F20: SIM | G20: 42122 | H20: 63.81 | I20: Editora Pressagio | J20: Full Tarot Deck | K20: =CONCATENATE(TEXT(A20,"0000"),(TEXT(G20,"aaaammdd"))) -> 001920150428
A21: 20 | B21: The Golden TSAR Tarot | C21: Lo Scarabeo | D21: Pietro Alligo, Atanas A. Atanassov | E21: SIM | F21: SIM | G21: 42133 | H21: 0 | I21: Presente | J21: Full Tarot Deck | K21: =CONCATENATE(TEXT(A21,"0000"),(TEXT(G21,"aaaammdd"))) -> 002020150509
A22: 21 | B22: Golden Dawn Tarot | C22: US Games Inc. | D22: Robert Wang / Israel Regardie | E22: SIM | F22: SIM | G22: 42176 | H22: 100 | I22: Simbólika | J22: Full Tarot Deck | K22: =CONCATENATE(TEXT(A22,"0000"),(TEXT(G22,"aaaammdd"))) -> 002120150621
A23: 22 | B23: New Visions of Rider Waite | C23: Lo Scarabeo | D23: Pietro Alligo, Raul Cestaro, Gianluca Cestaro | E23: SIM | F23: SIM | G23: 42176 | H23: 82 | I23: Simbólika | J23: Full Tarot Deck | K23: =CONCATENATE(TEXT(A23,"0000"),(TEXT(G23,"aaaammdd"))) -> 002220150621
A24: 23 | B24: Crowley Thoth Grande | C24: US Games Inc. | D24: Aleister Crowley / Frieda Harris | E24: SIM | F24: SIM | G24: 42183 | H24: 150 | I24: O Argonauta - Feira Mistica Paulista | J24: Full Tarot Deck | K24: =CONCATENATE(TEXT(A24,"0000"),(TEXT(G24,"aaaammdd"))) -> 002320150628
A25: 24 | B25: Russian Tarot of St. Petersburg Deck | C25: US Games Inc. | D25: Yury Shakov | E25: SIM | F25: SIM | G25: 42183 | H25: 100 | I25: O Argonauta - Feira Mistica Paulista | J25: Full Tarot Deck | K25: =CONCATENATE(TEXT(A25,"0000"),(TEXT(G25,"aaaammdd"))) -> 002420150628
A26: 25 | B26: ISIS Version of Tarot de Marseille | C26: ISIS Osiris | D26: TADAHIRO ONUMA / SUMI ONUMA | E26: Não | F26: Não | G26: 42145 | H26: 127.2 | I26: Direto do Autor | J26: Full Tarot Deck | K26: =CONCATENATE(TEXT(A26,"0000"),(TEXT(G26,"aaaammdd"))) -> 002520150521
A27: 26 | B27: Harmonious Tarot - Taro da Harmonia | C27: Lo Scarabeo | D27: Walter Crane, Ernest Fitzpatrick | E27: SIM | F27: SIM | G27: 42212 | H27: 98 | I27: Simbólika | J27: Full Tarot Deck | K27: =CONCATENATE(TEXT(A27,"0000"),(TEXT(G27,"aaaammdd"))) -> 002620150727
A28: 27 | B28: Tarot of the Mystic Spiral - Taro da Espiral Mistica | C28: Lo Scarabeo | D28: Giovanni Pelosini, Giuseppe Palumbo | E28: SIM | F28: SIM | G28: 42212 | H28: 79 | I28: Simbólika | J28: Full Tarot Deck | K28: =CONCATENATE(TEXT(A28,"0000"),(TEXT(G28,"aaaammdd"))) -> 002720150727
A29: 28 | B29: El Gran Tarot Esoterico | C29: Naipes Heraclio Fournier | E29: SIM | F29: SIM | G29: 42212 | H29: 77.4 | I29: Simbólika | J29: Full Tarot Deck | K29: =CONCATENATE(TEXT(A29,"0000"),(TEXT(G29,"aaaammdd"))) -> 002820150727
A30: 29 | B30: The Hermetic Tarot from Golden Dawn | C30: US Games Inc. | D30: Godfrey Dowson | E30: SIM | F30: SIM | G30: 42218 | H30: 145 | I30: O Argonauta - Feira Mistica Paulista | J30: Full Tarot Deck | K30: =CONCATENATE(TEXT(A30,"0000"),(TEXT(G30,"aaaammdd"))) -> 002920150802
A31: 30 | B31: Symbolon Grande | C31: AGM Müller Urania | D31: Ingrid Zinnel, Peter Orban & Thea Weller | E31: SIM | F31: SIM | G31: 42218 | H31: 130 | I31: O Argonauta - Feira Mistica Paulista | J31: Oracle 78 Cards | K31: =CONCATENATE(TEXT(A31,"0000"),(TEXT(G31,"aaaammdd"))) -> 003020150802
A32: 31 | B32: Tarot de Marseille de Francois Chosson 1736 | C32: Yves Reynaud | D32: Yves Reynaud | E32: Não | F32: Não | G32: 42225 | H32: 200 | I32: O Argonauta - Feira Mistica Paulista | J32: Full Tarot Deck | K32: =CONCATENATE(TEXT(A32,"0000"),(TEXT(G32,"aaaammdd"))) -> 003120150809
A33: 32 | B33: Le Tarot de Marseille | C33: Naipes Heraclio Fournier | E33: SIM | F33: SIM | G33: 42240 | H33: 93 | I33: Simbólika | J33: Full Tarot Deck | K33: =CONCATENATE(TEXT(A33,"0000"),(TEXT(G33,"aaaammdd"))) -> 003220150824
A34: 33 | B34: Morgan-Greer | C34: US Games Inc. | D34: Bill F. Greer with Lloyd Morgan | E34: SIM | F34: SIM | G34: 42248 | H34: 89 | I34: O Argonauta - Feira Mistica Paulista | J34: Full Tarot Deck | K34: =CONCATENATE(TEXT(A34,"0000"),(TEXT(G34,"aaaammdd"))) -> 003320150901
A35: 34 | B35: Rider Waite Tarot | C35: US Games Inc. | D35: Pamela Colman Smith | E35: SIM | F35: SIM | G35: 42248 | H35: 89 | I35: O Argonauta - Feira Mistica Paulista | J35: Full Tarot Deck | K35: =CONCATENATE(TEXT(A35,"0000"),(TEXT(G35,"aaaammdd"))) -> 003420150901
A36: 35 | B36: Tarot de marseille 1760 | C36: CAMOIN | D36: Alexandre JODOROWSKY / Philippe CAMOIN | E36: SIM | F36: SIM | G36: 42256 | H36: 174.9 | I36: Direto com o Editor | J36: Full Tarot Deck | K36: =CONCATENATE(TEXT(A36,"0000"),(TEXT(G36,"aaaammdd"))) -> 003520150909
A37: 36 | B37: Haindl Tarot | C37: US Games Inc. | D37: Hermann Haindl | E37: SIM | F37: SIM | G37: 42265 | H37: 79 | I37: Casa de Bruxa de Sto. André | J37: Full Tarot Deck | K37: =CONCATENATE(TEXT(A37,"0000"),(TEXT(G37,"aaaammdd"))) -> 003620150918
A38: 37 | B38: O Tarot dos Boêmios Tarot Papus-Goulinat | C38: N/A | D38: Papus | E38: Não | F38: Não | G38: 42266 | H38: 40 | I38: Sebo Poesia Santo André | J38: Full Tarot Deck | K38: =CONCATENATE(TEXT(A38,"0000"),(TEXT(G38,"aaaammdd"))) -> 003720150919
A39: 38 | B39: Marselha Generico | C39: Editora Planeta | E39: Não | F39: Não | G39: 42266 | H39: 15 | I39: Sebo Poesia Santo André | J39: Full Tarot Deck | K39: =CONCATENATE(TEXT(A39,"0000"),(TEXT(G39,"aaaammdd"))) -> 003820150919
A40: 39 | B40: Tarot Universal Salvador dalí | C40: Ever Green | D40: Johannes Iebig | E40: SIM | F40: Não | G40: 42270 | H40: 95 | I40: Sebo Poesia Santo André | J40: Full Tarot Deck | K40: =CONCATENATE(TEXT(A40,"0000"),(TEXT(G40,"aaaammdd"))) -> 003920150923
...

Sheet CdBr
A1: Sequencial | B1: =Tarot_Decks!K1 -> Chave Primária
A2: =Tarot_Decks!A2 -> 1 | B2: =Tarot_Decks!K2 -> 000120140716
A3: =Tarot_Decks!A3 -> 2 | B3: =Tarot_Decks!K3 -> 000220140716
A4: =Tarot_Decks!A4 -> 3 | B4: =Tarot_Decks!K4 -> 000320140827
A5: =Tarot_Decks!A5 -> 4 | B5: =Tarot_Decks!K5 -> 000420140827
A6: =Tarot_Decks!A6 -> 5 | B6: =Tarot_Decks!K6 -> 000520140829
A7: =Tarot_Decks!A7 -> 6 | B7: =Tarot_Decks!K7 -> 000620140918
A8: =Tarot_Decks!A8 -> 7 | B8: =Tarot_Decks!K8 -> 000720141201
A9: =Tarot_Decks!A9 -> 8 | B9: =Tarot_Decks!K9 -> 000820141201
A10: =Tarot_Decks!A10 -> 9 | B10: =Tarot_Decks!K10 -> 000920141211
A11: =Tarot_Decks!A11 -> 10 | B11: =Tarot_Decks!K11 -> 001020141223
A12: =Tarot_Decks!A12 -> 11 | B12: =Tarot_Decks!K12 -> 001120150116
A13: =Tarot_Decks!A13 -> 12 | B13: =Tarot_Decks!K13 -> 001220150224
... A194: =Tarot_Decks!A194 -> 193 | B194: =Tarot_Decks!K194 -> 019320231117

Sheet Action Figures
A1: Nome do Action | B1: Data | C1: Onde comprei | D1: Valor | E1: Status | F1: OBS
A2: Kriska Barchenowa Lingerie ver. (PVC Figure) Alphamax 1/7 Sky Tube | B2: 40587 | C2: http://www.1999.co.jp/eng/ | D2: 5,780 yen | E2: Received | F2: Aguardando CORREIOS
A3: Ghostbusters Bishoujo Lucy Complete | B3: 40605 | C3: http://www.amiami.com | D3: 5,430 Yen | E3: Received | F3: Aguardando Envio
A4: Androids Miniactions | B4: 40629 | C4: http://www.deadzebra.com | D4: $24.14 USD | E4: Received
A5: Sexy girl "Canal" 6" | B5: 40694 | C5: http://myworld.ebay.com/ekinyangyiwei | D5: $26.50 USD | E5: Received
A6: Marvel Bishoujo Statue ELEKTRA Kotobukiya 1/7 Bishoujo Statue | B6: 40738 | C6: http://www.1999.co.jp/eng/ | D6: 5,270 yen | E6: Received | F6: Late September 2011
A7: Marvel Bishoujo Mystique Kotobukiya 1/7 Bishoujo Statue | B7: 40738 | C7: http://www.1999.co.jp/eng/ | D7: 5,270 yen | E7: Received | F7: Late December 2011
A8: MARVEL BISHOUJO - X-23 Complete Figure | B8: 40774 | C8: http://www.amiami.com | D8: 4,950 Yen | E8: Canceled | F8: March 2012
A9: Marvel Bishoujo Statue Emma Frost Kotobukiya 1/8 Bishoujo Statue | B9: 40777 | C9: http://www.1999.co.jp/eng/ | D9: 5,580 Yen | E9: Received | F9: Aguardando CORREIOS
A10: Nariko | B10: 40973 | C10: http://myworld.ebay.com/toymania168/ | D10: $26,95 USD | E10: Received | F10: No Tracking ID
A11: Super Sonico -Nurse Ver.- (PVC Figure) | B11: 40978 | C11: http://www.1999.co.jp/eng/ | D11: 7,043 yen | E11: Canceled | F11: Late Aug 2012
A12: Megurine Luka Tony ver. *Special Price 20%OFF (PVC Figure) | B12: 40978 | C12: http://www.1999.co.jp/eng/ | D12: 6,704 yen | E12: Canceled | F12: Late Jul 2012
A13: Christie Monteiro Tekken Bishoujo - Kotobukiya | B13: 41023 | C13: http://www.allcenter.com.br | D13: 208.12 | E13: Received | F13: Barrado pela operação Maré Vermelha
A14: Batman - Wacky Wobbler | B14: 41031 | C14: http://www.allcenter.com.br | D14: 76.96 | E14: Received | F14: entrega errada. Devolvido
A15: Alisa Ilynichna Amiera (PVC Figure) | B15: 01/05/25012 | C15: http://www.1999.co.jp/eng/ | D15: 6,630 Yen | E15: Received | F15: Late Jul 2012
A16: Witchblade Estátua De Resina 30cm Altura Fantástica!!! | B16: 41053 | C16: http://www.mercadolivre.com.br/brasil/ml/org_prod.p_main?it_s=MLB&it_n=239082157 | D16: 175 | E16: Received
A17: Scott Pilgrim | B17: 41065 | C17: www.limitededition.com.br | D17: 109 | E17: Received
A18: Poison IVY Bishoujo | B18: 41065 | C18: www.limitededition.com.br | D18: 219 | E18: Received
A19: MegaHouse 814624 Yamato Girls Collection Space Battleship Yamato 2199 Mori Yuki Battleship Cloth Ver. (PVC Figure) 1/8 | B19: 41390 | C19: http://www.1999.co.jp/eng/ | D19: 9,070 yen | E19: Received

Sheet Planejamento 2014
A1: Item # | B1: Ano | C1: Descrição | D1: Status | F1: Item # | G1: Ano | H1: Certificações necessárias | I1: Status
A2: 1 | B2: 2014 | C2: Quitar débitos no banco, positivando as contas | D2: OK | F2: 1 | G2: 2014 | H2: Linux LPI-101
A3: 2 | B3: 2014 | C3: Pagar financiamento do Santander | D3: OK | F3: 2 | G3: 2014 | H3: Linux LPI-102
A4: 3 | B4: 2014 | C4: Trocar de Emprego | D4: OK | F4: 3 | G4: 2015 | H4: ITIL v3
A5: 4 | B5: 2014 | C5: Voltar a reter provisoes para imprevistos | F5: 4 | G5: 2015 | H5: Cobit 4.1
A6: 5 | B6: 2014 | C6: Cortar custos excedentes ?!?!?! | F6: 5 | G6: 2015 | H6: Scrum Master?
A7: 6 | B7: 2014 | C7: Terminar todas as materias MBA | D7: OK | F7: 6 | G7: 2015 | H7: SAP ???
A8: 7 | B8: 2014 | C8: Fazer o TCC do MBA | D8: OK | F8: 7 | G8: 2015 | H8: Protheus
A9: 8 | B9: 2014 | C9: Pagar GGM4 EchoSports | D9: OK | F9: 8 | G9: 2015 | H9: ERP ToTVS
A10: 9 | B10: 2014 | C10: Reduzir custos com moradia (Aluguel condominio) | F10: 9 | G10: 2015 | H10: PMI
A11: 10 | B11: 2014 | C11: Comprar um AP em SCS | F11: 10
A12: 1 | B12: 2015 | F12: 11
A13: 2 | B13: 2015 | F13: 12
A14: 3 | B14: 2015 | F14: 13
A15: 4 | B15: 2015 | F15: 14
A16: 5 | B16: 2015 | F16: 15
A17: 6 | B17: 2015 | F17: 16
A18: 7 | B18: 2015 | F18: 17
A19: 8 | B19: 2015 | F19: 18
A20: 9 | B20: 2015 | F20: 19
A21: 10 | B21: 2015 | F21: 20

Sheet Combustivel P208 Griffe Busines
A1: Seq | B1: Data | C1: Kilometragem | D1: Vlr Litro | E1: Valor total | F1: Tipo | G1: LtoTotal | H1: KmRodados | I1: Dias | J1: Km/Litro | K1: Km/Dia | L1: Lt/Dia | M1: R$/Dia | N1: R$/KM
A2: 1 | B2: 43381 | C2: 2 | D2: 4.789 | E2: 150 | F2: Gasolina | G2: =IF(E2<>"",E2/D2,"") -> 31.321779
A3: 2 | B3: 43400 | C3: 194 | D3: 4.899 | E3: 150 | F3: Gasolina | G3: =IF(E3<>"",E3/D3,"") -> 30.618494 | H3: =IF(C3="","",C3-C2) -> 192 | I3: =IF(B3="","",B3-B2) -> 19 | J3: =IF(H3="","",H3/G2) -> 6.12992 | K3: =IF(H3<>"",IF(I3>0,H3/I3,H3),"" ) -> 10.105263 | L3: =IF(I3="","",IF(I3=0,G3,G2/I3)) -> 1.6485147 | M3: =IF(I3="","",IF(I3=0,E2,E2/I3)) -> 7.8947368 | N3: =IF(H3="","",E2/H3) -> 0.78125
A4: 3 | B4: 43414 | C4: 419 | D4: 4.499 | E4: 235.66 | F4: Gasolina | G4: =IF(E4<>"",E4/D4,"") -> 52.380529 | H4: =IF(C4="","",C4-C3) -> 225 | I4: =IF(B4="","",B4-B3) -> 14 | J4: =IF(H4="","",H4/G3) -> 7.3485 | K4: =IF(H4<>"",IF(I4>0,H4/I4,H4),"" ) -> 16.071429 | L4: =IF(I4="","",IF(I4=0,G4,G3/I4)) -> 2.1870353 | M4: =IF(I4="","",IF(I4=0,E3,E3/I4)) -> 10.714286 | N4: =IF(H4="","",E3/H4) -> 0.66666667
A5: 4 | B5: 43434 | C5: 641 | D5: 4.599 | E5: 144.36 | F5: Gasolina | G5: =IF(E5<>"",E5/D5,"") -> 31.389432 | H5: =IF(C5="","",C5-C4) -> 222 | I5: =IF(B5="","",B5-B4) -> 20 | J5: =IF(H5="","",H5/G4) -> 4.2382161 | K5: =IF(H5<>"",IF(I5>0,H5/I5,H5),"" ) -> 11.1 | L5: =IF(I5="","",IF(I5=0,G5,G4/I5)) -> 2.6190265 | M5: =IF(I5="","",IF(I5=0,E4,E4/I5)) -> 11.783 | N5: =IF(H5="","",E4/H5) -> 1.0615315
A6: 5 | B6: 43436 | C6: 1045 | D6: 4.398 | E6: 122.07 | F6: Gasolina | G6: =IF(E6<>"",E6/D6,"") -> 27.755798 | H6: =IF(C6="","",C6-C5) -> 404 | I6: =IF(B6="","",B6-B5) -> 2 | J6: =IF(H6="","",H6/G5) -> 12.870574 | K6: =IF(H6<>"",IF(I6>0,H6/I6,H6),"" ) -> 202 | L6: =IF(I6="","",IF(I6=0,G6,G5/I6)) -> 15.694716 | M6: =IF(I6="","",IF(I6=0,E5,E5/I6)) -> 72.18 | N6: =IF(H6="","",E5/H6) -> 0.35732673
A7: 6 | B7: 43449 | C7: 1582 | D7: 4.399 | E7: 35 | F7: Gasolina | G7: =IF(E7<>"",E7/D7,"") -> 7.9563537 | H7: =IF(C7="","",C7-C6) -> 537 | I7: =IF(B7="","",B7-B6) -> 13 | J7: =IF(H7="","",H7/G6) -> 19.347309 | K7: =IF(H7<>"",IF(I7>0,H7/I7,H7),"" ) -> 41.307692 | L7: =IF(I7="","",IF(I7=0,G7,G6/I7)) -> 2.1350614 | M7: =IF(I7="","",IF(I7=0,E6,E6/I7)) -> 9.39 | N7: =IF(H7="","",E6/H7) -> 0.22731844
A8: 7 | B8: 43454 | C8: 1647 | D8: 4.399 | E8: 227.82 | F8: Gasolina | G8: =IF(E8<>"",E8/D8,"") -> 51.789043 | H8: =IF(C8="","",C8-C7) -> 65 | I8: =IF(B8="","",B8-B7) -> 5 | J8: =IF(H8="","",H8/G7) -> 8.1695714 | K8: =IF(H8<>"",IF(I8>0,H8/I8,H8),"" ) -> 13 | L8: =IF(I8="","",IF(I8=0,G8,G7/I8)) -> 1.5912707 | M8: =IF(I8="","",IF(I8=0,E7,E7/I8)) -> 7 | N8: =IF(H8="","",E7/H8) -> 0.53846154
A9: 8 | B9: 43467 | C9: 2148 | D9: 4.298 | E9: 188.19 | F9: Gasolina | G9: =IF(E9<>"",E9/D9,"") -> 43.785482 | H9: =IF(C9="","",C9-C8) -> 501 | I9: =IF(B9="","",B9-B8) -> 13 | J9: =IF(H9="","",H9/G8) -> 9.6738609 | K9: =IF(H9<>"",IF(I9>0,H9/I9,H9),"" ) -> 38.538462 | L9: =IF(I9="","",IF(I9=0,G9,G8/I9)) -> 3.9837725 | M9: =IF(I9="","",IF(I9=0,E8,E8/I9)) -> 17.524615 | N9: =IF(H9="","",E8/H9) -> 0.45473054
A10: 9 | B10: 43479 | C10: 2673 | D10: 4.287 | E10: 110 | F10: Gasolina | G10: =IF(E10<>"",E10/D10,"") -> 25.658969 | H10: =IF(C10="","",C10-C9) -> 525 | I10: =IF(B10="","",B10-B9) -> 12 | J10: =IF(H10="","",H10/G9) -> 11.990276 | K10: =IF(H10<>"",IF(I10>0,H10/I10,H10),"" ) -> 43.75 | L10: =IF(I10="","",IF(I10=0,G10,G9/I10)) -> 3.6487901 | M10: =IF(I10="","",IF(I10=0,E9,E9/I10)) -> 15.6825 | N10: =IF(H10="","",E9/H10) -> 0.35845714
A11: 10 | B11: 43493 | C11: 2855 | D11: 4.299 | E11: 50 | F11: Gasolina | G11: =IF(E11<>"",E11/D11,"") -> 11.630612 | H11: =IF(C11="","",C11-C10) -> 182 | I11: =IF(B11="","",B11-B10) -> 14 | J11: =IF(H11="","",H11/G10) -> 7.0930364 | K11: =IF(H11<>"",IF(I11>0,H11/I11,H11),"" ) -> 13 | L11: =IF(I11="","",IF(I11=0,G11,G10/I11)) -> 1.8327835 | M11: =IF(I11="","",IF(I11=0,E10,E10/I11)) -> 7.8571429 | N11: =IF(H11="","",E10/H11) -> 0.6043956
A12: 11 | B12: 43498 | C12: 2938 | D12: 4.299 | E12: 226 | F12: Gasolina | G12: =IF(E12<>"",E12/D12,"") -> 52.570365 | H12: =IF(C12="","",C12-C11) -> 83 | I12: =IF(B12="","",B12-B11) -> 5 | J12: =IF(H12="","",H12/G11) -> 7.13634 | K12: =IF(H12<>"",IF(I12>0,H12/I12,H12),"" ) -> 16.6 | L12: =IF(I12="","",IF(I12=0,G12,G11/I12)) -> 2.3261224 | M12: =IF(I12="","",IF(I12=0,E11,E11/I12)) -> 10 | N12: =IF(H12="","",E11/H12) -> 0.60240964
A13: 12 | B13: 43525 | C13: 3273 | D13: 3.999 | E13: 211.73 | F13: Gasolina | G13: =IF(E13<>"",E13/D13,"") -> 52.945736 | H13: =IF(C13="","",C13-C12) -> 335 | I13: =IF(B13="","",B13-B12) -> 27 | J13: =IF(H13="","",H13/G12) -> 6.3724115 | K13: =IF(H13<>"",IF(I13>0,H13/I13,H13),"" ) -> 12.407407 | L13: =IF(I13="","",IF(I13=0,G13,G12/I13)) -> 1.9470506 | M13: =IF(I13="","",IF(I13=0,E12,E12/I13)) -> 8.3703704 | N13: =IF(H13="","",E12/H13) -> 0.67462687
A14: 13 | B14: 43530 | C14: 3697 | D14: 4.199 | E14: 80 | F14: Gasolina | G14: =IF(E14<>"",E14/D14,"") -> 19.052155 | H14: =IF(C14="","",C14-C13) -> 424 | I14: =IF(B14="","",B14-B13) -> 5 | J14: =IF(H14="","",H14/G13) -> 8.0081991 | K14: =IF(H14<>"",IF(I14>0,H14/I14,H14),"" ) -> 84.8 | L14: =IF(I14="","",IF(I14=0,G14,G13/I14)) -> 10.589147 | M14: =IF(I14="","",IF(I14=0,E13,E13/I14)) -> 42.346 | N14: =IF(H14="","",E13/H14) -> 0.49936321
... A210: 209 | B210: 45949 | C210: 48077 | D210: 6.29 | E210: 150 | F210: Gasolina | G210: =IF(E210<>"",E210/D210,"") -> 23.847377 | H210: =IF(C210="","",C210-C209) -> 224 | I210: =IF(B210="","",B210-B209) -> 1 | J210: =IF(H210="","",H210/G209) -> 9.2437333 | K210: =IF(H210<>"",IF(I210>0,H210/I210,H210),"" ) -> 224 | L210: =IF(I210="","",IF(I210=0,G210,G209/I210)) -> 24.232633 | M210: =IF(I210="","",IF(I210=0,E209,E209/I210)) -> 150 | N210: =IF(H210="","",E209/H210) -> 0.66964286
A211: 210 | B211: 45957 | C211: =48493-120 -> 48373 | D211: 5.99 | E211: 150 | F211: Gasolina | G211: =IF(E211<>"",E211/D211,"") -> 25.041736 | H211: =IF(C211="","",C211-C210) -> 296 | I211: =IF(B211="","",B211-B210) -> 8 | J211: =IF(H211="","",H211/G210) -> 12.412267 | K211: =IF(H211<>"",IF(I211>0,H211/I211,H211),"" ) -> 37 | L211: =IF(I211="","",IF(I211=0,G211,G210/I211)) -> 2.9809221 | M211: =IF(I211="","",IF(I211=0,E210,E210/I211)) -> 18.75 | N211: =IF(H211="","",E210/H211) -> 0.50675676
A212: 211 | B212: 45978 | C212: 48645 | D212: 5.79 | E212: 120 | F212: Gasolina | G212: =IF(E212<>"",E212/D212,"") -> 20.725389 | H212: =IF(C212="","",C212-C211) -> 272 | I212: =IF(B212="","",B212-B211) -> 21 | J212: =IF(H212="","",H212/G211) -> 10.861867 | K212: =IF(H212<>"",IF(I212>0,H212/I212,H212),"" ) -> 12.952381 | L212: =IF(I212="","",IF(I212=0,G212,G211/I212)) -> 1.1924636 | M212: =IF(I212="","",IF(I212=0,E211,E211/I212)) -> 7.1428571 | N212: =IF(H212="","",E211/H212) -> 0.55147059
A213: 212 | B213: 45987 | C213: 48754 | D213: 5.79 | E213: 100 | F213: Gasolina | G213: =IF(E213<>"",E213/D213,"") -> 17.271157 | H213: =IF(C213="","",C213-C212) -> 109 | I213: =IF(B213="","",B213-B212) -> 9 | J213: =IF(H213="","",H213/G212) -> 5.25925 | K213: =IF(H213<>"",IF(I213>0,H213/I213,H213),"" ) -> 12.111111 | L213: =IF(I213="","",IF(I213=0,G213,G212/I213)) -> 2.302821 | M213: =IF(I213="","",IF(I213=0,E212,E212/I213)) -> 13.333333 | N213: =IF(H213="","",E212/H213) -> 1.1009174
A214: 213 | B214: 46003 | C214: 48892 | D214: 6.29 | E214: 100 | F214: Gasolina | G214: =IF(E214<>"",E214/D214,"") -> 15.898251 | H214: =IF(C214="","",C214-C213) -> 138 | I214: =IF(B214="","",B214-B213) -> 16 | J214: =IF(H214="","",H214/G213) -> 7.9902 | K214: =IF(H214<>"",IF(I214>0,H214/I214,H214),"" ) -> 8.625 | L214: =IF(I214="","",IF(I214=0,G214,G213/I214)) -> 1.0794473 | M214: =IF(I214="","",IF(I214=0,E213,E213/I214)) -> 6.25 | N214: =IF(H214="","",E213/H214) -> 0.72463768
A215: 214 | B215: 46007 | C215: 49000 | D215: 5.99 | E215: 100 | F215: Gasolina | G215: =IF(E215<>"",E215/D215,"") -> 16.694491 | H215: =IF(C215="","",C215-C214) -> 108 | I215: =IF(B215="","",B215-B214) -> 4 | J215: =IF(H215="","",H215/G214) -> 6.7932 | K215: =IF(H215<>"",IF(I215>0,H215/I215,H215),"" ) -> 27 | L215: =IF(I215="","",IF(I215=0,G215,G214/I215)) -> 3.9745628 | M215: =IF(I215="","",IF(I215=0,E214,E214/I215)) -> 25 | N215: =IF(H215="","",E214/H215) -> 0.92592593
A216: 215 | B216: 46011 | C216: 49025 | D216: 5.99 | E216: 200 | F216: Gasolina | G216: =IF(E216<>"",E216/D216,"") -> 33.388982 | H216: =IF(C216="","",C216-C215) -> 25 | I216: =IF(B216="","",B216-B215) -> 4 | J216: =IF(H216="","",H216/G215) -> 1.4975 | K216: =IF(H216<>"",IF(I216>0,H216/I216,H216),"" ) -> 6.25 | L216: =IF(I216="","",IF(I216=0,G216,G215/I216)) -> 4.1736227 | M216: =IF(I216="","",IF(I216=0,E215,E215/I216)) -> 25 | N216: =IF(H216="","",E215/H216) -> 4
A217: 216 | B217: 46024 | C217: 49423 | D217: 6.29 | E217: 200 | F217: Gasolina | G217: =IF(E217<>"",E217/D217,"") -> 31.796502 | H217: =IF(C217="","",C217-C216) -> 398 | I217: =IF(B217="","",B217-B216) -> 13 | J217: =IF(H217="","",H217/G216) -> 11.9201 | K217: =IF(H217<>"",IF(I217>0,H217/I217,H217),"" ) -> 30.615385 | L217: =IF(I217="","",IF(I217=0,G217,G216/I217)) -> 2.5683832 | M217: =IF(I217="","",IF(I217=0,E216,E216/I217)) -> 15.384615 | N217: =IF(H217="","",E216/H217) -> 0.50251256
A218: 217 | B218: 46055 | C218: 49914 | D218: 6.09 | E218: 150 | F218: Gasolina | G218: =IF(E218<>"",E218/D218,"") -> 24.630542 | H218: =IF(C218="","",C218-C217) -> 491 | I218: =IF(B218="","",B218-B217) -> 31 | J218: =IF(H218="","",H218/G217) -> 15.44195 | K218: =IF(H218<>"",IF(I218>0,H218/I218,H218),"" ) -> 15.83871 | L218: =IF(I218="","",IF(I218=0,G218,G217/I218)) -> 1.0256936 | M218: =IF(I218="","",IF(I218=0,E217,E217/I218)) -> 6.4516129 | N218: =IF(H218="","",E217/H218) -> 0.40733198
A219: 218 | B219: 46068 | C219: 50043 | D219: 5.89 | E219: 150 | F219: Gasolina | G219: =IF(E219<>"",E219/D219,"") -> 25.466893 | H219: =IF(C219="","",C219-C218) -> 129 | I219: =IF(B219="","",B219-B218) -> 13 | J219: =IF(H219="","",H219/G218) -> 5.2374 | K219: =IF(H219<>"",IF(I219>0,H219/I219,H219),"" ) -> 9.9230769 | L219: =IF(I219="","",IF(I219=0,G219,G218/I219)) -> 1.8946571 | M219: =IF(I219="","",IF(I219=0,E218,E218/I219)) -> 11.538462 | N219: =IF(H219="","",E218/H219) -> 1.1627907
A220: 219 | B220: 46074 | C220: 50175 | D220: 6.09 | E220: 150 | F220: Gasolina | G220: =IF(E220<>"",E220/D220,"") -> 24.630542 | H220: =IF(C220="","",C220-C219) -> 132 | I220: =IF(B220="","",B220-B219) -> 6 | J220: =IF(H220="","",H220/G219) -> 5.1832 | K220: =IF(H220<>"",IF(I220>0,H220/I220,H220),"" ) -> 22 | L220: =IF(I220="","",IF(I220=0,G220,G219/I220)) -> 4.2444822 | M220: =IF(I220="","",IF(I220=0,E219,E219/I220)) -> 25 | N220: =IF(H220="","",E219/H220) -> 1.1363636
A221: 220 | B221: 46075 | C221: 50439 | D221: 6.39 | E221: 150 | F221: Gasolina | G221: =IF(E221<>"",E221/D221,"") -> 23.474178 | H221: =IF(C221="","",C221-C220) -> 264 | I221: =IF(B221="","",B221-B220) -> 1 | J221: =IF(H221="","",H221/G220) -> 10.7184 | K221: =IF(H221<>"",IF(I221>0,H221/I221,H221),"" ) -> 264 | L221: =IF(I221="","",IF(I221=0,G221,G220/I221)) -> 24.630542 | M221: =IF(I221="","",IF(I221=0,E220,E220/I221)) -> 150 | N221: =IF(H221="","",E220/H221) -> 0.56818182
A222: 221 | B222: 46093 | C222: 50876 | D222: 6.89 | E222: 150 | F222: Gasolina | G222: =IF(E222<>"",E222/D222,"") -> 21.770682 | H222: =IF(C222="","",C222-C221) -> 437 | I222: =IF(B222="","",B222-B221) -> 18 | J222: =IF(H222="","",H222/G221) -> 18.6162 | K222: =IF(H222<>"",IF(I222>0,H222/I222,H222),"" ) -> 24.277778 | L222: =IF(I222="","",IF(I222=0,G222,G221/I222)) -> 1.304121 | M222: =IF(I222="","",IF(I222=0,E221,E221/I222)) -> 8.3333333 | N222: =IF(H222="","",E221/H222) -> 0.34324943
A223: 222 | B223: 46098 | C223: 50997 | D223: 6.39 | E223: 150 | F223: Gasolina | G223: =IF(E223<>"",E223/D223,"") -> 23.474178 | H223: =IF(C223="","",C223-C222) -> 121 | I223: =IF(B223="","",B223-B222) -> 5 | J223: =IF(H223="","",H223/G222) -> 5.5579333 | K223: =IF(H223<>"",IF(I223>0,H223/I223,H223),"" ) -> 24.2 | L223: =IF(I223="","",IF(I223=0,G223,G222/I223)) -> 4.3541364 | M223: =IF(I223="","",IF(I223=0,E222,E222/I223)) -> 30 | N223: =IF(H223="","",E222/H223) -> 1.2396694
... A230: 229 | B230: 46155 | C230: 52441 | D230: 6.19 | E230: 100 | F230: Gasolina | G230: =IF(E230<>"",E230/D230,"") -> 16.155089 | H230: =IF(C230="","",C230-C229) -> 474 | I230: =IF(B230="","",B230-B229) -> 10 | J230: =IF(H230="","",H230/G229) -> 16.0923 | K230: =IF(H230<>"",IF(I230>0,H230/I230,H230),"" ) -> 47.4 | L230: =IF(I230="","",IF(I230=0,G230,G229/I230)) -> 2.9455081 | M230: =IF(I230="","",IF(I230=0,E229,E229/I230)) -> 20 | N230: =IF(H230="","",E229/H230) -> 0.42194093
A231: 230 | G231: =IF(E231<>"",E231/D231,"") | H231: =IF(C231="","",C231-C230) | I231: =IF(B231="","",B231-B230) | J231: =IF(H231="","",H231/G230) | K231: =IF(H231<>"",IF(I231>0,H231/I231,H231),"" ) | L231: =IF(I231="","",IF(I231=0,G231,G230/I231)) | M231: =IF(I231="","",IF(I231=0,E230,E230/I231)) | N231: =IF(H231="","",E230/H231)
A232: 231 | G232: =IF(E232<>"",E232/D232,"") | H232: =IF(C232="","",C232-C231) | I232: =IF(B232="","",B232-B231) | J232: =IF(H232="","",H232/G231) | K232: =IF(H232<>"",IF(I232>0,H232/I232,H232),"" ) | L232: =IF(I232="","",IF(I232=0,G232,G231/I232)) | M232: =IF(I232="","",IF(I232=0,E231,E231/I232)) | N232: =IF(H232="","",E231/H232)
A233: 232 | G233: =IF(E233<>"",E233/D233,"") | H233: =IF(C233="","",C233-C232) | I233: =IF(B233="","",B233-B232) | J233: =IF(H233="","",H233/G232) | K233: =IF(H233<>"",IF(I233>0,H233/I233,H233),"" ) | L233: =IF(I233="","",IF(I233=0,G233,G232/I233)) | M233: =IF(I233="","",IF(I233=0,E232,E232/I233)) | N233: =IF(H233="","",E232/H233)
A234: 233 | G234: =IF(E234<>"",E234/D234,"") | H234: =IF(C234="","",C234-C233) | I234: =IF(B234="","",B234-B233) | J234: =IF(H234="","",H234/G233) | K234: =IF(H234<>"",IF(I234>0,H234/I234,H234),"" ) | L234: =IF(I234="","",IF(I234=0,G234,G233/I234)) | M234: =IF(I234="","",IF(I234=0,E233,E233/I234)) | N234: =IF(H234="","",E233/H234)
A235: 234 | G235: =IF(E235<>"",E235/D235,"") | H235: =IF(C235="","",C235-C234) | I235: =IF(B235="","",B235-B234) | J235: =IF(H235="","",H235/G234) | K235: =IF(H235<>"",IF(I235>0,H235/I235,H235),"" ) | L235: =IF(I235="","",IF(I235=0,G235,G234/I235)) | M235: =IF(I235="","",IF(I235=0,E234,E234/I235)) | N235: =IF(H235="","",E234/H235)
A236: 235 | G236: =IF(E236<>"",E236/D236,"") | H236: =IF(C236="","",C236-C235) | I236: =IF(B236="","",B236-B235) | J236: =IF(H236="","",H236/G235) | K236: =IF(H236<>"",IF(I236>0,H236/I236,H236),"" ) | L236: =IF(I236="","",IF(I236=0,G236,G235/I236)) | M236: =IF(I236="","",IF(I236=0,E235,E235/I236)) | N236: =IF(H236="","",E235/H236)
A237: 236 | G237: =IF(E237<>"",E237/D237,"") | H237: =IF(C237="","",C237-C236) | I237: =IF(B237="","",B237-B236) | J237: =IF(H237="","",H237/G236) | K237: =IF(H237<>"",IF(I237>0,H237/I237,H237),"" ) | L237: =IF(I237="","",IF(I237=0,G237,G236/I237)) | M237: =IF(I237="","",IF(I237=0,E236,E236/I237)) | N237: =IF(H237="","",E236/H237)
A238: 237 | G238: =IF(E238<>"",E238/D238,"") | H238: =IF(C238="","",C238-C237) | I238: =IF(B238="","",B238-B237) | J238: =IF(H238="","",H238/G237) | K238: =IF(H238<>"",IF(I238>0,H238/I238,H238),"" ) | L238: =IF(I238="","",IF(I238=0,G238,G237/I238)) | M238: =IF(I238="","",IF(I238=0,E237,E237/I238)) | N238: =IF(H238="","",E237/H238)
A239: 238 | G239: =IF(E239<>"",E239/D239,"") | H239: =IF(C239="","",C239-C238) | I239: =IF(B239="","",B239-B238) | J239: =IF(H239="","",H239/G238) | K239: =IF(H239<>"",IF(I239>0,H239/I239,H239),"" ) | L239: =IF(I239="","",IF(I239=0,G239,G238/I239)) | M239: =IF(I239="","",IF(I239=0,E238,E238/I239)) | N239: =IF(H239="","",E238/H239)
A240: 239 | G240: =IF(E240<>"",E240/D240,"") | H240: =IF(C240="","",C240-C239) | I240: =IF(B240="","",B240-B239) | J240: =IF(H240="","",H240/G239) | K240: =IF(H240<>"",IF(I240>0,H240/I240,H240),"" ) | L240: =IF(I240="","",IF(I240=0,G240,G239/I240)) | M240: =IF(I240="","",IF(I240=0,E239,E239/I240)) | N240: =IF(H240="","",E239/H240)
A241: 240 | G241: =IF(E241<>"",E241/D241,"") | H241: =IF(C241="","",C241-C240) | I241: =IF(B241="","",B241-B240) | J241: =IF(H241="","",H241/G240) | K241: =IF(H241<>"",IF(I241>0,H241/I241,H241),"" ) | L241: =IF(I241="","",IF(I241=0,G241,G240/I241)) | M241: =IF(I241="","",IF(I241=0,E240,E240/I241)) | N241: =IF(H241="","",E240/H241)
...

Sheet Senhas
A1: Local | B1: user ID | C1: Password | D1: Tipo | E1: Atualização Dados | F1: Ativo | G1: Exportado
A2: 404notfound.com.br | B2: GarGaMel | C2: sync750v | D2: Online Services | E2: 37249 | F2: N
A3: AIM | B3: Hardrappel | C3: p_280277 | D3: Instant Message | F3: Y
A4: americanas.com | B4: luizcarlin | C4: sync750v | D4: Shopping | E4: 39559 | F4: Y
A5: apinfo.com | B5: 274549748 | C5: sync750v | D5: Jobs | E5: 38913 | F5: N
A6: arquivo-x.com | B6: gargamel | C6: LAC280277 | D6: e-mail | F6: N
A7: arremate.com | B7: hardrappel | C7: sync750v | D7: Shopping | E7: 38854 | F7: Y
A8: unibanco.com.br | B8: 7007 -105877-3 | C8: 6478 | D8: Internet Banking | E8: 38715 | F8: N
A9: bancoreal.com.br | B9: luizcarlin 0247 9705879 | C9: sync750v | D9: Internet Banking | E9: 37249 | F9: N
A10: banespa.com.br | B10: acarlin - 920009805 | C10: 250680 | D10: Internet Banking | E10: 38715 | F10: Y
A11: blogger.com.br | B11: cyberspawn | C11: sync750v | D11: Blogger | E11: 37497 | F11: n
A12: Bol.com.br | B12: gargamel_lac | C12: sync750v | D12: e-mail | E12: 37249 | F12: N
A13: borland.com | B13: hardrappel | C13: sync750v | D13: Online Services | E13: 38715 | F13: Y
A14: Cdpoint.com.br | B14: hardrappel | C14: sync750v | D14: Video/Music | E14: 38715 | F14: Y
A15: Cell.com.br | B15: lcarlin | C15: 5876 | D15: Cell Services | F15: N
A16: ceviu.com.br | B16: luizcarlin | C16: sync750v | D16: Jobs | E16: 38715 | F16: Y
A17: cipsga.org.br | B17: gargamel | C17: sync750v | D17: Online Services | E17: 37258 | F17: N
A18: citibank.com.br | B18: luizcarlin | C18: luizao123 | D18: Internet Banking | E18: 38562 | F18: N
A19: cjb.net | B19: hardrappel | C19: sync750v | D19: URL redir | E19: 37249 | F19: N
A20: cjb.net | B20: luizao-gargamel | C20: sync750v | D20: URL redir | E20: 37249 | F20: N
A21: cjb.net | B21: marlboroman | C21: sync750v | D21: URL redir | E21: 37249 | F21: N
A22: Comvc | B22: gargamel -220213 | C22: 280277 | D22: Instant Message | F22: N
A23: counter.li.org | B23: 153198 | C23: 153198-84399 | D23: Counter | E23: 38715 | F23: Y
A24: digitis.com | B24: gargamel_do_rappel | C24: sync750v | D24: Counter | E24: 37249 | F24: N
A25: dromadario.com.br | B25: gargamel | C25: sync750v | D25: Online Services | E25: 37249 | F25: N
A26: ebit.com.br | B26: gargamel@ldapalm.com.br | C26: sync750v | D26: Shopping | E26: 37249 | F26: N
A27: elefante.com.br | B27: luiz.carlin@ibest.com.br | C27: sync750v | D27: Online Services | E27: 38660 | F27: N
A28: ezdir.com.br | B28: hardrappel@icqmail.com | C28: sync750v | D28: URL redir | E28: 37249 | F28: N
A29: freedrive.com | B29: hardrappel | C29: sync750v | D29: Online Services | E29: 37251 | F29: N
A30: gmail.com | B30: luiz.carlin | C30: bucet@69 | D30: e-mail | E30: 38562 | F30: Y | G30: Y
A31: Grupos.com.br | B31: gargamel@ldapalm.com.br | C31: sync750v | D31: Mailling | E31: 37249 | F31: N
A32: Grupos.com.br | B32: gargamel_do_rappel@yahoo.com | C32: sync750v | D32: Mailling | E32: 37249 | F32: N
A33: hotmail.com | B33: gargamel_lac | C33: sync750v | D33: e-mail/Mess | E33: 37249 | F33: N
A34: hotmail.com | B34: luiz_carlin | C34: bucet@69 | D34: e-mail/Mess | E34: 38715 | F34: Y
A35: hpg.com.br | B35: luizcarlin | C35: sync750v | D35: Hosting | E35: 37249 | F35: n | G35: Y
A36: hpg.com.br | B36: hardrappel | C36: sync750v | D36: Hosting | E36: 37249 | F36: N
A37: HSBC Wap | B37: 03650900434 | C37: 9230 | D37: WAP | F37: N
A38: Hsbc.com.br - Novo | B38: 0365 0900434 | C38: sync750 | D38: Internet Banking | E38: 37418 | F38: N
A39: Hsbc.com.br - Velho | B39: 0365 0900434 | C39: 5876 | D39: Internet Banking | F39: N
A40: mercadolivre.com.br | B40: gargamaiden | C40: sync750v | D40: Shopping | E40: 38715 | F40: Y
...

Sheet Documentos
A1: Tipo | B1: Numero | C1: Emissao | D1: Validade
A2: RG | B2: 27.454.974-8 ssp/SP | C2: 33367 | D2: 42692
A3: CPF | B3: 212.785.028-90 | C3: 34569
A4: PIS | B4: 127.17912.50.0 | C4: 36293
A5: CNH | B5: 1028869406 | C5: 38035 | D5: 39860
A6: Reservista | B6: RA 14123203556-0 | C6: 34928
A7: Titulo Eleitor | B7: 02373638601-16 Zn 307 Sec 0346 | C7: 38062 | D7: 237363860116
A8: CLT / CTPS | B8: nº 031175 Serie 00218-sp | C8: 35452
A9: CREA | B9: 12.855/D | C9: 38531
A10: Passaporte | B10: FR932650 | C10: 42690 | D10: 46342
A12: Rg Cris | B12: 7.262.861-6 | C12: 34661
A13: Rg Cris | B13: 2.717.198 SSP/DF | C13: 38429
A14: CPF Cris | B14: 041.568.599-08
A15: Titulo Eleitor | B15: 0073032550671
A16: Habilitação | B16: 01962042677
A19: CG Titan 125
A20: RENAVAN | B20: 82001972-0
A21: CHASSIS | B21: 9C2JC30104R067155
A22: MOTOR | B22: JC30E14067155
A23: PLACA | B23: ALL-9328
A25: Careca
A26: CPF | B26: 453.870.528-49
A27: RG | B27: 1.774.386-SSP/SP
B29: 195.378.368-60
A31: CBX Twister 250
A32: RENAVAN | B32: 894942670
A33: CHASSIS | B33: 9C2MC35007R00973
A34: MOTOR
A35: PLACA | B35: DPW-0854
A37: Peugeot 206
A38: RENAVAN | B38: 863321879
A39: CHASSIS | B39: 9362A7LZ96B013136
A40: MOTOR
A41: PLACA | B41: DQH-4141

Sheet FGTS
A1: Data | B1: act Digital | C1: Claro | D1: DXC | E1: Global Hitss | F1: Global Telecom | G1: NTT Data_Everis | H1: TIM | I1: UniTech | J1: Bearing Point | K1: Exactus | L1: Digitep | M1: Total | N1: Diff Mês Anterior | O1: Diff_Mes_Anterior | P1: Projecao | Q1: Total_Projecao | R1: Diff_Projecao | S1: Meta
A2: 41187 | F2: 6302.66 | G2: 0 | H2: 77117.46 | I2: 2920.83 | J2: 2922.37 | K2: 1310.51 | L2: 48.12 | M2: =SUM(H2:L2) -> 84319.29
A3: 41220 | F3: 6302.66 | G3: 0 | H3: 78098.13 | I3: 2928.03 | J3: 2929.57 | K3: 1313.74 | L3: 48.23 | M3: =SUM(H3:L3) -> 85317.7 | N3: =IF(M3<>0,M3-M2,"") -> 998.41 | O3: =IF(N3<>"",(N3/M3),"") -> 0.011702261
A4: 41253 | F4: 6333.78 | G4: 0 | H4: 78984.76 | I4: 2942.48 | J4: 2944.03 | K4: 1320.21 | L4: 48.45 | M4: =SUM(H4:L4) -> 86239.93 | N4: =IF(M4<>0,M4-M3,"") -> 922.23 | O4: =IF(N4<>"",(N4/M4),"") -> 0.01069377 | P4: =IF(N3<>"",M3+N3,"") -> 86316.11 | R4: =IF(M4>0,M4-P4,"") -> -76.18 | S4: =IF(M4>=P4,"SIM","Não") -> Não
A5: 41284 | F5: 6349.39 | G5: 0 | H5: 79679.93 | I5: 2949.73 | J5: 2951.28 | K5: 1323.46 | L5: 48.56 | M5: =SUM(H5:L5) -> 86952.96 | N5: =IF(M5<>0,M5-M4,"") -> 713.03 | O5: =IF(N5<>"",(N5/M5),"") -> 0.0082001809 | P5: =IF(N4<>"",M4+N4,"") -> 87162.16 | R5: =IF(M5>0,M5-P5,"") -> -209.2 | S5: =IF(M5>=P5,"SIM","Não") -> Não
A6: 41315 | F6: 6365.04 | G6: 0 | H6: 80647.67 | I6: 2957 | J6: 2958.55 | K6: 1326.72 | L6: 48.67 | M6: =SUM(H6:L6) -> 87938.61 | N6: =IF(M6<>0,M6-M5,"") -> 985.65 | O6: =IF(N6<>"",(N6/M6),"") -> 0.011208387 | P6: =IF(N5<>"",M5+N5,"") -> 87665.99 | R6: =IF(M6>0,M6-P6,"") -> 272.62 | S6: =IF(M6>=P6,"SIM","Não") -> SIM
A7: 41343 | F7: 6380.73 | G7: 0 | H7: 81869.12 | I7: 2964.29 | J7: 2965.84 | K7: 1329.99 | L7: 48.79 | M7: =SUM(H7:L7) -> 89178.03 | N7: =IF(M7<>0,M7-M6,"") -> 1239.42 | O7: =IF(N7<>"",(N7/M7),"") -> 0.013898266 | P7: =IF(N6<>"",M6+N6,"") -> 88924.26 | R7: =IF(M7>0,M7-P7,"") -> 253.77 | S7: =IF(M7>=P7,"SIM","Não") -> SIM
A8: 41374 | F8: 6396.46 | G8: 0 | H8: 83411.85 | I8: 2971.59 | J8: 2973.15 | K8: 1333.29 | L8: 48.91 | M8: =SUM(H8:L8) -> 90738.79 | N8: =IF(M8<>0,M8-M7,"") -> 1560.76 | O8: =IF(N8<>"",(N8/M8),"") -> 0.017200582 | P8: =IF(N7<>"",M7+N7,"") -> 90417.45 | R8: =IF(M8>0,M8-P8,"") -> 321.34 | S8: =IF(M8>=P8,"SIM","Não") -> SIM
A9: 41404 | F9: 6412.23 | G9: 0 | H9: 85712.45 | I9: 2978.91 | J9: 2980.48 | K9: 1336.54 | L9: 49.03 | M9: =SUM(H9:L9) -> 93057.41 | N9: =IF(M9<>0,M9-M8,"") -> 2318.62 | O9: =IF(N9<>"",(N9/M9),"") -> 0.024916017 | P9: =IF(N8<>"",M8+N8,"") -> 92299.55 | R9: =IF(M9>0,M9-P9,"") -> 757.86 | S9: =IF(M9>=P9,"SIM","Não") -> SIM
A10: 41435 | F10: 6428.04 | G10: 0 | H10: 87537.78 | I10: 2986.25 | J10: 2987.82 | K10: 1339.83 | L10: 49.15 | M10: =SUM(H10:L10) -> 94900.83 | N10: =IF(M10<>0,M10-M9,"") -> 1843.42 | O10: =IF(N10<>"",(N10/M10),"") -> 0.019424698 | P10: =IF(N9<>"",M9+N9,"") -> 95376.03 | R10: =IF(M10>0,M10-P10,"") -> -475.2 | S10: =IF(M10>=P10,"SIM","Não") -> Não
A11: 41465 | F11: 6443.89 | G11: 0 | H11: 88780.28 | I11: 2993.61 | J11: 2995.18 | K11: 1343.13 | L11: 49.27 | M11: =SUM(H11:L11) -> 96161.47 | N11: =IF(M11<>0,M11-M10,"") -> 1260.64 | O11: =IF(N11<>"",(N11/M11),"") -> 0.013109617 | P11: =IF(N10<>"",M10+N10,"") -> 96744.25 | R11: =IF(M11>0,M11-P11,"") -> -582.78 | S11: =IF(M11>=P11,"SIM","Não") -> Não
A12: 41496 | F12: 6461.12 | G12: 0 | H12: 91474.27 | I12: 3001.61 | J12: 3003.19 | K12: 1346.72 | L12: 49.4 | M12: =SUM(H12:L12) -> 98875.19 | N12: =IF(M12<>0,M12-M11,"") -> 2713.72 | O12: =IF(N12<>"",(N12/M12),"") -> 0.027445914 | P12: =IF(N11<>"",M11+N11,"") -> 97422.11 | R12: =IF(M12>0,M12-P12,"") -> 1453.08 | S12: =IF(M12>=P12,"SIM","Não") -> SIM
A13: 41527 | F13: 6477.05 | G13: 0 | H13: 92213.73 | I13: 3009.01 | J13: 3010.59 | K13: 1350.04 | L13: 49.52 | M13: =SUM(H13:L13) -> 99632.89 | N13: =IF(M13<>0,M13-M12,"") -> 757.7 | O13: =IF(N13<>"",(N13/M13),"") -> 0.0076049184 | P13: =IF(N12<>"",M12+N12,"") -> 101588.91 | R13: =IF(M13>0,M13-P13,"") -> -1956.02 | S13: =IF(M13>=P13,"SIM","Não") -> Não
A14: 41557 | F14: 6477.05 | G14: 0 | H14: 92213.73 | I14: 3009.01 | J14: 3010.59 | K14: 1350.04 | L14: 49.52 | M14: =SUM(H14:L14) -> 99632.89 | N14: =IF(M14<>0,M14-M13,"") -> 0 | O14: =IF(N14<>"",(N14/M14),"") -> 0 | P14: =IF(N13<>"",M13+N13,"") -> 100390.59 | R14: =IF(M14>0,M14-P14,"") -> -757.7 | S14: =IF(M14>=P14,"SIM","Não") -> Não
A15: 41588 | F15: 6515.53 | G15: 0 | H15: 94301.2 | I15: 3026.88 | J15: 3028.47 | K15: 1358.05 | L15: 49.8 | M15: =SUM(H15:L15) -> 101764.4 | N15: =IF(M15<>0,M15-M14,"") -> 2131.51 | O15: =IF(N15<>"",(N15/M15),"") -> 0.020945537 | P15: =IF(N14<>"",M14+N14,"") -> 99632.89 | R15: =IF(M15>0,M15-P15,"") -> 2131.51 | S15: =IF(M15>=P15,"SIM","Não") -> SIM
... A24: 42073 | F24: 6847.49 | G24: 0 | H24: 1234.34 | I24: 3181.05 | J24: 3182.74 | K24: 1427.16 | L24: 52.26 | M24: =SUM(H24:L24) -> 9077.55 | N24: =IF(M24<>0,M24-M23,"") -> 23.82 | O24: =IF(N24<>"",(N24/M24),"") -> 0.0026240561 | P24: =IF(N23<>"",M23+N23,"") -> 10338.24 | R24: =IF(M24>0,M24-P24,"") -> -1260.69 | S24: =IF(M24>=P24,"SIM","Não") -> Não
A25: 42104 | F25: 6873.27 | G25: 626.39 | H25: 1238.98 | I25: 3193.02 | J25: 3194.72 | K25: 1432.53 | L25: 52.45 | M25: =SUM(G25:L25) -> 9738.09 | N25: =IF(M25<>0,M25-M24,"") -> 660.54 | O25: =IF(N25<>"",(N25/M25),"") -> 0.06783055 | P25: =IF(N24<>"",M24+N24,"") -> 9101.37 | R25: =IF(M25>0,M25-P25,"") -> 636.72 | S25: =IF(M25>=P25,"SIM","Não") -> SIM
A26: 42134 | F26: 6897.61 | G26: 1276.61 | H26: 1243.36 | I26: 3204.32 | J26: 3206.03 | K26: 1437.6 | L26: 52.63 | M26: =SUM(G26:L26) -> 10420.55 | N26: =IF(M26<>0,M26-M25,"") -> 682.46 | O26: =IF(N26<>"",(N26/M26),"") -> 0.065491745 | P26: =IF(N25<>"",M25+N25,"") -> 10398.63 | R26: =IF(M26>0,M26-P26,"") -> 21.92 | S26: =IF(M26>=P26,"SIM","Não") -> SIM
A27: 42165 | F27: 6922.59 | G27: 2482.05 | H27: 1247.86 | I27: 3215.92 | J27: 3217.64 | K27: 1442.8 | L27: 52.82 | M27: =SUM(G27:L27) -> 11659.09 | N27: =IF(M27<>0,M27-M26,"") -> 1238.54 | O27: =IF(N27<>"",(N27/M27),"") -> 0.10622956 | P27: =IF(N26<>"",M26+N26,"") -> 11103.01 | R27: =IF(M27>0,M27-P27,"") -> 556.08 | S27: =IF(M27>=P27,"SIM","Não") -> SIM
A28: 42195 | F28: 6952.23 | G28: 3433.72 | H28: 1253.2 | I28: 3229.69 | J28: 3231.42 | K28: 1448.97 | L28: 53.04 | M28: =SUM(G28:L28) -> 12650.04 | N28: =IF(M28<>0,M28-M27,"") -> 990.95 | O28: =IF(N28<>"",(N28/M28),"") -> 0.078335721 | P28: =IF(N27<>"",M27+N27,"") -> 12897.63 | R28: =IF(M28>0,M28-P28,"") -> -247.59 | S28: =IF(M28>=P28,"SIM","Não") -> Não
A29: 42226 | F29: 6985.43 | G29: 5202.73 | H29: 1259.18 | I29: 3245.11 | J29: 3246.85 | K29: 1455.89 | L29: 53.29 | M29: =SUM(G29:L29) -> 14463.05 | N29: =IF(M29<>0,M29-M28,"") -> 1813.01 | O29: =IF(N29<>"",(N29/M29),"") -> 0.12535461 | P29: =IF(N28<>"",M28+N28,"") -> 13640.99 | R29: =IF(M29>0,M29-P29,"") -> 822.06 | S29: =IF(M29>=P29,"SIM","Não") -> SIM
A30: 42257 | F30: 7015.72 | G30: 6452.04 | H30: 1264.64 | I30: 3259.18 | J30: 3260.93 | K30: 1462.2 | L30: 53.52 | M30: =SUM(G30:L30) -> 15752.51 | N30: =IF(M30<>0,M30-M29,"") -> 1289.46 | O30: =IF(N30<>"",(N30/M30),"") -> 0.081857431 | P30: =IF(N29<>"",M29+N29,"") -> 16276.06 | R30: =IF(M30>0,M30-P30,"") -> -523.55 | S30: =IF(M30>=P30,"SIM","Não") -> Não
A31: 42287 | F31: 7046.51 | G31: 7653.62 | H31: 1270.19 | I31: 3273.48 | J31: 3275.24 | K31: 1468.61 | L31: 53.75 | M31: =SUM(G31:L31) -> 16994.89 | N31: =IF(M31<>0,M31-M30,"") -> 1242.38 | O31: =IF(N31<>"",(N31/M31),"") -> 0.07310315 | P31: =IF(N30<>"",M30+N30,"") -> 17041.97 | R31: =IF(M31>0,M31-P31,"") -> -47.08 | S31: =IF(M31>=P31,"SIM","Não") -> Não
A32: 42318 | F32: 7076.52 | G32: 8830.13 | H32: 1275.6 | I32: 3287.42 | J32: 3289.19 | K32: 1474.86 | L32: 53.97 | M32: =SUM(G32:L32) -> 18211.17 | N32: =IF(M32<>0,M32-M31,"") -> 1216.28 | O32: =IF(N32<>"",(N32/M32),"") -> 0.066787581 | P32: =IF(N31<>"",M31+N31,"") -> 18237.27 | R32: =IF(M32>0,M32-P32,"") -> -26.1 | S32: =IF(M32>=P32,"SIM","Não") -> Não
A33: 42348 | F33: 7103.17 | G33: 10094.8 | H33: 1280.4 | I33: 3299.8 | J33: 3301.57 | K33: 1480.41 | L33: 54.17 | M33: =SUM(G33:L33) -> 19511.15 | N33: =IF(M33<>0,M33-M32,"") -> 1299.98 | O33: =IF(N33<>"",(N33/M33),"") -> 0.066627544 | P33: =IF(N32<>"",M32+N32,"") -> 19427.45 | R33: =IF(M33>0,M33-P33,"") -> 83.7 | S33: =IF(M33>=P33,"SIM","Não") -> SIM
A34: 42379 | F34: 7136.7 | G34: 11922.27 | H34: 1286.44 | I34: 3315.37 | J34: 3317.15 | K34: 1487.39 | L34: 54.42 | M34: =SUM(G34:L34) -> 21383.04 | N34: =IF(M34<>0,M34-M33,"") -> 1871.89 | O34: =IF(N34<>"",(N34/M34),"") -> 0.087540874 | P34: =IF(N33<>"",M33+N33,"") -> 20811.13 | R34: =IF(M34>0,M34-P34,"") -> 571.91 | S34: =IF(M34>=P34,"SIM","Não") -> SIM
A35: 42410 | F35: 7163.74 | G35: 12864.11 | H35: 1291.31 | I35: 3327.93 | J35: 3329.71 | K35: 1493.02 | L35: 54.62 | M35: =SUM(G35:L35) -> 22360.7 | N35: =IF(M35<>0,M35-M34,"") -> 977.66 | O35: =IF(N35<>"",(N35/M35),"") -> 0.043722245 | P35: =IF(N34<>"",M34+N34,"") -> 23254.93 | R35: =IF(M35>0,M35-P35,"") -> -894.23 | S35: =IF(M35>=P35,"SIM","Não") -> Não
A36: 42439 | F36: 7188.27 | G36: 13665.53 | H36: 1295.73 | I36: 3339.32 | J36: 3341.11 | K36: 1498.13 | L36: 54.8 | M36: =SUM(G36:L36) -> 23194.62 | N36: =IF(M36<>0,M36-M35,"") -> 833.92 | O36: =IF(N36<>"",(N36/M36),"") -> 0.035953165 | P36: =IF(N35<>"",M35+N35,"") -> 23338.36 | R36: =IF(M36>0,M36-P36,"") -> -143.74 | S36: =IF(M36>=P36,"SIM","Não") -> Não
... A80: 43779 | F80: 8252.78 | G80: 0 | H80: 0 | I80: 0 | J80: 0 | K80: 0 | L80: 0 | M80: =SUM(G80:L80) -> 0 | N80: =IF(M80<>0,M80-M79,"") | O80: =IF(N80<>"",(N80/M80),"") | P80: =IF(N79<>"",M79+N79,"") | R80: =IF(M80>0,M80-P80,"") | S80: =IF(M80>=P80,"SIM","Não") -> Não
A81: 43809 | E81: 540.01 | F81: 8252.78 | G81: 0 | H81: 0 | I81: 0 | J81: 0 | K81: 0 | L81: 0 | M81: =SUM(E81:L81) -> 8792.79 | N81: =IF(M81<>0,M81-M80,"") -> 8792.79 | O81: =IF(N81<>"",(N81/M81),"") -> 1 | P81: =IF(N80<>"",M80+N80,"") | R81: =IF(M81>0,M81-P81,"") -> #VALUE! | S81: =IF(M81>=P81,"SIM","Não") -> Não
A82: 43840 | E82: 1321.35 | F82: 8293.53 | G82: 0 | H82: 0 | I82: 0 | J82: 0 | K82: 0 | L82: 0 | M82: =SUM(E82:L82) -> 9614.88 | N82: =IF(M82<>0,M82-M81,"") -> 822.09 | O82: =IF(N82<>"",(N82/M82),"") -> 0.085501847 | P82: =IF(N81<>"",AVERAGE(N79:N81),"") -> 8792.79 | Q82: =M81+P82 -> 17585.58 | R82: =IF(M82>0,M82-Q82,"") -> -7970.7 | S82: =IF(M82>=P82,"SIM","Não") -> SIM
A83: 43871 | E83: 2044.61 | F83: 8313.98 | G83: 0 | H83: 0 | I83: 0 | J83: 0 | K83: 0 | L83: 0 | M83: =SUM(E83:L83) -> 10358.59 | N83: =IF(M83<>0,M83-M82,"") -> 743.71 | O83: =IF(N83<>"",(N83/M83),"") -> 0.071796451 | P83: =IF(N82<>"",AVERAGE(N80:N82),"") -> 4807.44 | Q83: =M82+P83 -> 14422.32 | R83: =IF(M83>0,M83-Q83,"") -> -4063.73 | S83: =IF(M83>=P83,"SIM","Não") -> SIM
A84: 43900 | E84: 2769.66 | F84: 8334.48 | G84: 0 | H84: 0 | I84: 0 | J84: 0 | K84: 0 | L84: 0 | M84: =SUM(E84:L84) -> 11104.14 | N84: =IF(M84<>0,M84-M83,"") -> 745.55 | O84: =IF(N84<>"",(N84/M84),"") -> 0.067141625 | P84: =IF(N83<>"",AVERAGE(N81:N83),"") -> 3452.8633 | Q84: =M83+P84 -> 13811.453 | R84: =IF(M84>0,M84-Q84,"") -> -2707.3133 | S84: =IF(M84>=P84,"SIM","Não") -> SIM
A85: 43931 | E85: 0 | F85: 8355.03 | G85: 0 | H85: 0 | I85: 0 | J85: 0 | K85: 0 | L85: 0 | M85: =SUM(E85:L85) -> 8355.03 | N85: =IF(M85<>0,M85-M84,"") -> -2749.11 | O85: =IF(N85<>"",(N85/M85),"") -> -0.32903652 | P85: =IF(N84<>"",AVERAGE(N82:N84),"") -> 770.45 | Q85: =M84+P85 -> 11874.59 | R85: =IF(M85>0,M85-Q85,"") -> -3519.56 | S85: =IF(M85>=P85,"SIM","Não") -> SIM
A86: 44326 | E86: 10.14 | F86: 8782.83 | G86: 0 | H86: 0 | I86: 0 | J86: 0 | K86: 0 | L86: 0 | M86: =SUM(E86:L86) -> 8792.97 | N86: =IF(M86<>0,M86-M85,"") -> 437.94 | O86: =IF(N86<>"",(N86/M86),"") -> 0.049805697 | P86: =IF(N85<>"",AVERAGE(N83:N85),"") -> -419.95 | Q86: =M85+P86 -> 7935.08 | R86: =IF(M86>0,M86-Q86,"") -> 857.89 | S86: =IF(M86>=P86,"SIM","Não") -> SIM
A87: 44357 | D87: 660.81 | E87: 10.16 | F87: 8804.48 | G87: 0 | H87: 0 | I87: 0 | J87: 0 | K87: 0 | L87: 0 | M87: =SUM(D87:L87) -> 9475.45 | N87: =IF(M87<>0,M87-M86,"") -> 682.48 | O87: =IF(N87<>"",(N87/M87),"") -> 0.072026131 | P87: =IF(N86<>"",AVERAGE(N84:N86),"") -> -521.87333 | Q87: =M86+P87 -> 8271.0967 | R87: =IF(M87>0,M87-Q87,"") -> 1204.3533 | S87: =IF(M87>=Q87,"SIM","Não") -> SIM
A88: 44387 | D88: 1921.1 | E88: 10.18 | F88: 8826.19 | G88: 0 | H88: 0 | I88: 0 | J88: 0 | K88: 0 | L88: 0 | M88: =SUM(D88:L88) -> 10757.47 | N88: =IF(M88<>0,M88-M87,"") -> 1282.02 | O88: =IF(N88<>"",(N88/M88),"") -> 0.11917486 | P88: =IF(N87<>"",AVERAGE(N85:N87),"") -> -542.89667 | Q88: =M87+P88 -> 8932.5533 | R88: =IF(M88>0,M88-Q88,"") -> 1824.9167 | S88: =IF(M88>=Q88,"SIM","Não") -> SIM
A89: 44418 | D89: 2869.84 | E89: 10.2 | F89: 8847.95 | G89: 0 | H89: 0 | I89: 0 | J89: 0 | K89: 0 | L89: 0 | M89: =SUM(D89:L89) -> 11727.99 | N89: =IF(M89<>0,M89-M88,"") -> 970.52 | O89: =IF(N89<>"",(N89/M89),"") -> 0.082752458 | P89: =IF(N88<>"",AVERAGE(N86:N88),"") -> 800.81333 | Q89: =M88+P89 -> 11558.283 | R89: =IF(M89>0,M89-Q89,"") -> 169.70667 | S89: =IF(M89>=Q89,"SIM","Não") -> SIM
A90: 44449 | D90: 3820.92 | E90: 10.4 | F90: 9031.82 | G90: 0 | H90: 0 | I90: 0 | J90: 0 | K90: 0 | L90: 0 | M90: =SUM(D90:L90) -> 12863.14 | N90: =IF(M90<>0,M90-M89,"") -> 1135.15 | O90: =IF(N90<>"",(N90/M90),"") -> 0.088248282 | P90: =IF(N89<>"",AVERAGE(N87:N89),"") -> 978.34 | Q90: =M89+P90 -> 12706.33 | R90: =IF(M90>0,M90-Q90,"") -> 156.81 | S90: =IF(M90>=Q90,"SIM","Não") -> SIM
A91: 44479 | D91: 4774.35 | E91: 10.42 | F91: 9054.09 | G91: 0 | H91: 0 | I91: 0 | J91: 0 | K91: 0 | L91: 0 | M91: =SUM(D91:L91) -> 13838.86 | N91: =IF(M91<>0,M91-M90,"") -> 975.72 | O91: =IF(N91<>"",(N91/M91),"") -> 0.070505808 | P91: =IF(N90<>"",AVERAGE(N88:N90),"") -> 1129.23 | Q91: =IF(P91>0,M90+P91,"") -> 13992.37 | R91: =IF(M91>0,M91-Q91,"") -> -153.51 | S91: =IF(M91>=Q91,"SIM","Não") -> Não
...

Sheet Movimentações
B1: Credito | C1: Debito | D1: Saldo
A2: Real | B2: =Real!D580 -> 10158.79 | C2: =Real!E580 -> 10158.79 | D2: =B2-C2 -> 0
